<?xml version="1.0"?>
<robot name="indoor_mapper_bot" xmlns:xacro="http://ros.org/wiki/xacro">
  <xacro:property name="base_length" value="0.34" />
  <xacro:property name="base_width" value="0.25" />
  <xacro:property name="base_height" value="0.13" />
  <xacro:property name="wheel_radius" value="0.065" />
  <xacro:property name="wheel_width" value="0.035" />
  <xacro:property name="wheel_y" value="0.15" />

  <link name="base_footprint" />

  <joint name="base_footprint_joint" type="fixed">
    <parent link="base_footprint" />
    <child link="base_link" />
    <origin xyz="0 0 0" />
  </joint>

  <link name="base_link">
    <inertial>
      <origin xyz="0 0 0.065" />
      <mass value="3.2" />
      <inertia ixx="0.020" ixy="0" ixz="0" iyy="0.028" iyz="0" izz="0.038" />
    </inertial>
    <visual>
      <origin xyz="0 0 ${base_height / 2.0}" />
      <geometry>
        <box size="${base_length} ${base_width} ${base_height}" />
      </geometry>
      <material name="body_teal">
        <color rgba="0.05 0.36 0.40 1" />
      </material>
    </visual>
    <collision name="base_collision">
      <origin xyz="0 0 ${base_height / 2.0 + 0.012}" />
      <geometry>
        <box size="${base_length} ${base_width} ${base_height}" />
      </geometry>
    </collision>
  </link>

  <link name="left_wheel_link">
    <inertial>
      <mass value="0.30" />
      <inertia ixx="0.0007" ixy="0" ixz="0" iyy="0.0007" iyz="0" izz="0.0007" />
    </inertial>
    <visual>
      <origin xyz="0 0 0" rpy="1.57079632679 0 0" />
      <geometry>
        <cylinder radius="${wheel_radius}" length="${wheel_width}" />
      </geometry>
      <material name="wheel_black">
        <color rgba="0.02 0.02 0.02 1" />
      </material>
    </visual>
    <collision>
      <origin xyz="0 0 0" rpy="1.57079632679 0 0" />
      <geometry>
        <cylinder radius="${wheel_radius}" length="${wheel_width}" />
      </geometry>
    </collision>
  </link>

  <link name="right_wheel_link">
    <inertial>
      <mass value="0.30" />
      <inertia ixx="0.0007" ixy="0" ixz="0" iyy="0.0007" iyz="0" izz="0.0007" />
    </inertial>
    <visual>
      <origin xyz="0 0 0" rpy="1.57079632679 0 0" />
      <geometry>
        <cylinder radius="${wheel_radius}" length="${wheel_width}" />
      </geometry>
      <material name="wheel_black" />
    </visual>
    <collision>
      <origin xyz="0 0 0" rpy="1.57079632679 0 0" />
      <geometry>
        <cylinder radius="${wheel_radius}" length="${wheel_width}" />
      </geometry>
    </collision>
  </link>

  <link name="caster_link">
    <inertial>
      <mass value="0.1" />
      <inertia ixx="0.0001" ixy="0" ixz="0" iyy="0.0001" iyz="0" izz="0.0001" />
    </inertial>
    <visual>
      <geometry>
        <sphere radius="0.028" />
      </geometry>
      <material name="wheel_black" />
    </visual>
    <collision>
      <geometry>
        <sphere radius="0.028" />
      </geometry>
    </collision>
  </link>

  <link name="laser_link">
    <inertial>
      <mass value="0.2" />
      <inertia ixx="0.0004" ixy="0" ixz="0" iyy="0.0004" iyz="0" izz="0.0004" />
    </inertial>
    <visual>
      <geometry>
        <cylinder radius="0.045" length="0.04" />
      </geometry>
      <material name="laser_copper">
        <color rgba="0.95 0.48 0.12 1" />
      </material>
    </visual>
    <collision>
      <geometry>
        <cylinder radius="0.045" length="0.04" />
      </geometry>
    </collision>
  </link>

  <link name="camera_link">
    <inertial>
      <mass value="0.05" />
      <inertia ixx="0.00002" ixy="0" ixz="0" iyy="0.00002" iyz="0" izz="0.00002" />
    </inertial>
    <visual>
      <geometry>
        <box size="0.035 0.055 0.035" />
      </geometry>
      <material name="camera_black">
        <color rgba="0.01 0.01 0.01 1" />
      </material>
    </visual>
    <collision>
      <geometry>
        <box size="0.035 0.055 0.035" />
      </geometry>
    </collision>
  </link>

  <joint name="left_wheel_joint" type="continuous">
    <parent link="base_link" />
    <child link="left_wheel_link" />
    <origin xyz="0 ${wheel_y} ${wheel_radius}" />
    <axis xyz="0 1 0" />
  </joint>

  <joint name="right_wheel_joint" type="continuous">
    <parent link="base_link" />
    <child link="right_wheel_link" />
    <origin xyz="0 -${wheel_y} ${wheel_radius}" />
    <axis xyz="0 1 0" />
  </joint>

  <joint name="caster_joint" type="fixed">
    <parent link="base_link" />
    <child link="caster_link" />
    <origin xyz="-0.13 0 0.028" />
  </joint>

  <joint name="laser_joint" type="fixed">
    <parent link="base_link" />
    <child link="laser_link" />
    <origin xyz="0.08 0 0.19" />
  </joint>

  <joint name="camera_joint" type="fixed">
    <parent link="base_link" />
    <child link="camera_link" />
    <origin xyz="0.185 0 0.27" />
  </joint>

  <gazebo reference="base_footprint">
    <sensor type="contact" name="base_contact_sensor">
      <always_on>true</always_on>
      <update_rate>40</update_rate>
      <contact>
        <collision>base_footprint_fixed_joint_lump__base_collision_collision</collision>
      </contact>
      <plugin name="gazebo_ros_bumper" filename="libgazebo_ros_bumper.so">
        <robotNamespace>/</robotNamespace>
        <bumperTopicName>bumper</bumperTopicName>
        <frameName>base_link</frameName>
      </plugin>
    </sensor>
  </gazebo>

  <gazebo reference="base_link">
    <material>Gazebo/Green</material>
  </gazebo>

  <gazebo reference="left_wheel_link">
    <material>Gazebo/Black</material>
    <mu1>1.0</mu1>
    <mu2>1.0</mu2>
  </gazebo>

  <gazebo reference="right_wheel_link">
    <material>Gazebo/Black</material>
    <mu1>1.0</mu1>
    <mu2>1.0</mu2>
  </gazebo>

  <gazebo reference="laser_link">
    <material>Gazebo/Orange</material>
    <sensor type="ray" name="indoor_mapper_laser">
      <pose>0 0 0 0 0 0</pose>
      <visualize>false</visualize>
      <update_rate>12</update_rate>
      <ray>
        <scan>
          <horizontal>
            <samples>720</samples>
            <resolution>1</resolution>
            <min_angle>-3.14159265359</min_angle>
            <max_angle>3.14159265359</max_angle>
          </horizontal>
        </scan>
        <range>
          <min>0.12</min>
          <max>12.0</max>
          <resolution>0.01</resolution>
        </range>
        <noise>
          <type>gaussian</type>
          <mean>0.0</mean>
          <stddev>0.01</stddev>
        </noise>
      </ray>
      <plugin name="gazebo_ros_laser" filename="libgazebo_ros_laser.so">
        <robotNamespace>/</robotNamespace>
        <topicName>scan</topicName>
        <frameName>laser_link</frameName>
      </plugin>
    </sensor>
  </gazebo>

  <gazebo reference="camera_link">
    <material>Gazebo/Black</material>
    <sensor type="camera" name="robot_view_camera">
      <pose>0 0 0 0 0 0</pose>
      <visualize>false</visualize>
      <update_rate>15</update_rate>
      <camera>
        <horizontal_fov>1.047</horizontal_fov>
        <image>
          <width>640</width>
          <height>480</height>
          <format>R8G8B8</format>
        </image>
        <clip>
          <near>0.05</near>
          <far>20.0</far>
        </clip>
      </camera>
      <plugin name="gazebo_ros_robot_view_camera" filename="libgazebo_ros_camera.so">
        <robotNamespace>/</robotNamespace>
        <cameraName>robot_view</cameraName>
        <imageTopicName>image_raw</imageTopicName>
        <cameraInfoTopicName>camera_info</cameraInfoTopicName>
        <frameName>camera_link</frameName>
      </plugin>
    </sensor>
  </gazebo>

  <gazebo>
    <plugin name="indoor_mapper_diff_drive" filename="libgazebo_ros_diff_drive.so">
      <robotNamespace>/</robotNamespace>
      <legacyMode>false</legacyMode>
      <alwaysOn>true</alwaysOn>
      <updateRate>50</updateRate>
      <leftJoint>left_wheel_joint</leftJoint>
      <rightJoint>right_wheel_joint</rightJoint>
      <wheelSeparation>${2.0 * wheel_y}</wheelSeparation>
      <wheelDiameter>${2.0 * wheel_radius}</wheelDiameter>
      <wheelAcceleration>5.0</wheelAcceleration>
      <wheelTorque>5</wheelTorque>
      <commandTopic>cmd_vel</commandTopic>
      <odometryTopic>odom</odometryTopic>
      <odometrySource>world</odometrySource>
      <odometryFrame>odom</odometryFrame>
      <robotBaseFrame>base_link</robotBaseFrame>
      <publishWheelTF>false</publishWheelTF>
      <publishOdomTF>true</publishOdomTF>
      <publishWheelJointState>true</publishWheelJointState>
    </plugin>
  </gazebo>
</robot>
